Workbook
Name рассчитываемБИПЦ: [1]БИПЦ!$D$1

Sheet Прогноз
E1: 46181 | F1: 46181 | G1: 46163 | H1: 46163
A2: Дата | B2: -0.5 | E2: MoM | F2: YoY | G2: MoM | H2: YoY | I2: 3mmasaar
A3: 44562 | E3: 101.22 | F3: 108.84
A4: 44593 | E4: 100.94 | F4: 108.73
A5: 44621 | E5: 105.55 | F5: 113.29 | I5: =AVERAGE($E3:$E5)^12/100^11-100 -> 35.595184
A6: 44652 | E6: 103.28 | F6: 116 | I6: =AVERAGE($E4:$E6)^12/100^11-100 -> 46.89845
A7: 44682 | E7: 100.68 | F7: 116.31 | I7: =AVERAGE($E5:$E7)^12/100^11-100 -> 45.425701
A8: 44713 | E8: 99.32 | F8: 114.88 | I8: =AVERAGE($E6:$E8)^12/100^11-100 -> 13.938422
A9: 44743 | E9: 99.23 | F9: 113.75 | I9: =AVERAGE($E7:$E9)^12/100^11-100 -> -3.0368905
A10: 44774 | E10: 99.43 | F10: 112.92 | I10: =AVERAGE($E8:$E10)^12/100^11-100 -> -7.787386
A11: 44805 | E11: 100.33 | F11: 112.46 | I11: =AVERAGE($E9:$E11)^12/100^11-100 -> -3.9660258
A12: 44835 | E12: 100.66 | F12: 112.17 | I12: =AVERAGE($E10:$E12)^12/100^11-100 -> 1.6929966
A13: 44866 | E13: 100.26 | F13: 111.51 | I13: =AVERAGE($E11:$E13)^12/100^11-100 -> 5.1161898
A14: 44896 | E14: 100.57 | F14: 111.9 | I14: =AVERAGE($E12:$E14)^12/100^11-100 -> 6.1255331
A15: 44927 | E15: 101.13 | F15: 111.8 | I15: =AVERAGE($E13:$E15)^12/100^11-100 -> 8.1279436
A16: 44958 | E16: 100.75 | F16: 111.59 | I16: =AVERAGE($E14:$E16)^12/100^11-100 -> 10.252389
... A23: 45170 | E23: 101.75 | F23: 107.05 | I23: =AVERAGE($E21:$E23)^12/100^11-100 -> 9.0770906
A24: 45200 | B24: =E24-0.5 -> 99.96 | E24: 100.46 | F24: 106.84 | I24: =AVERAGE($E22:$E24)^12/100^11-100 -> 8.9039524
A25: 45231 | E25: 100.74 | F25: 107.34 | I25: =AVERAGE($E23:$E25)^12/100^11-100 -> 12.459572
A26: 45261 | E26: 100.29 | F26: 107.05 | I26: =AVERAGE($E24:$E26)^12/100^11-100 -> 6.1255331
A27: 45292 | E27: 100.87 | F27: 106.77 | I27: =AVERAGE($E25:$E27)^12/100^11-100 -> 7.8704026
A28: 45323 | E28: 100.53 | F28: 106.54 | I28: =AVERAGE($E26:$E28)^12/100^11-100 -> 6.9734306
A29: 45352 | E29: 100.53 | F29: 106.68 | I29: =AVERAGE($E27:$E29)^12/100^11-100 -> 7.9991028
A30: 45383 | E30: 100.38 | F30: 106.32 | I30: =AVERAGE($E28:$E30)^12/100^11-100 -> 5.9145235
A31: 45413 | E31: 100.94 | F31: 107.59 | I31: =AVERAGE($E29:$E31)^12/100^11-100 -> 7.6562147
A32: 45444 | E32: 100.18 | F32: 107.33 | I32: =AVERAGE($E30:$E32)^12/100^11-100 -> 6.1677812
A33: 45474 | E33: 101.07 | F33: 107.94 | I33: =AVERAGE($E31:$E33)^12/100^11-100 -> 9.1204146
A34: 45505 | E34: 100.09 | F34: 108.1 | I34: =AVERAGE($E32:$E34)^12/100^11-100 -> 5.4936577
A35: 45536 | E35: 100.62 | F35: 106.91 | I35: =AVERAGE($E33:$E35)^12/100^11-100 -> 7.3570066
A36: 45566 | E36: 101.02 | F36: 107.49 | I36: =AVERAGE($E34:$E36)^12/100^11-100 -> 7.1437535
... A50: 45992 | E50: 100.29 | F50: 105.28 | I50: =AVERAGE($E48:$E50)^12/100^11-100 -> 3.9497484
A51: 46023 | C51: =E51-100 -> 1.6 | D51: =F51-100 -> 6.07 | E51: 101.6 | F51: =ROUND(PRODUCT(E40:E51)/100^11,2) -> 106.07 | G51: 101.6 | H51: 106.07 | I51: =AVERAGE($E49:$E51)^12/100^11-100 -> 8.4722085
A52: 46054 | C52: =E52-100 -> 1.1 | D52: =F52-100 -> 5.82 | E52: 101.1 | F52: =ROUND(PRODUCT(E41:E52)/100^11,2) -> 105.82 | G52: 101.1 | H52: 105.82 | I52: =AVERAGE($E50:$E52)^12/100^11-100 -> 12.637884
A53: 46082 | C53: =E53-100 -> 0.54 | D53: =F53-100 -> 5.54 | E53: 100.54 | F53: =ROUND(PRODUCT(E42:E53)/100^11,2) -> 105.54 | G53: 100.54 | H53: 105.54 | I53: =AVERAGE($E51:$E53)^12/100^11-100 -> 13.758223
A54: 46113 | C54: =E54-100 -> -0.28 | D54: =F54-100 -> 4.69 | E54: 99.72 | F54: =ROUND(PRODUCT(E43:E54)/100^11,2) -> 104.69 | G54: 99.72 | H54: 104.69 | I54: =AVERAGE($E52:$E54)^12/100^11-100 -> 5.577708
A55: 46143 | C55: =E55-100 -> 0.1 | D55: =F55-100 -> 4.86 | E55: 100.1 | F55: =ROUND(PRODUCT(E44:E55)/100^11,2) -> 104.86 | G55: 99.9 | H55: 104.66 | I55: =AVERAGE($E53:$E55)^12/100^11-100 -> 1.4495421
A56: 46174 | C56: =E56-100 -> 0.3 | D56: =F56-100 -> 5.22 | E56: 100.3 | F56: =ROUND(PRODUCT(E45:E56)/100^11,2) -> 105.22 | G56: 100 | H56: 104.7 | I56: =AVERAGE($E54:$E56)^12/100^11-100 -> 0.48105741
A57: 46204 | C57: =E57-100 -> -0.1 | D57: =F57-100 -> 4.74 | E57: 99.9 | F57: =ROUND(PRODUCT(E46:E57)/100^11,2) -> 104.74 | G57: 99.9 | H57: 104.22 | I57: =AVERAGE($E55:$E57)^12/100^11-100 -> 1.206622
A58: 46235 | E58: 99.85 | F58: =ROUND(PRODUCT(E47:E58)/100^11,2) -> 105.18 | G58: 99.85 | H58: 104.66 | I58: =AVERAGE($E56:$E58)^12/100^11-100 -> 0.20018344
A59: 46266 | E59: 100.45 | F59: =ROUND(PRODUCT(E48:E59)/100^11,2) -> 104.61 | G59: 100.45 | H59: 104.09 | I59: =AVERAGE($E57:$E59)^12/100^11-100 -> 0.80293986
...

Sheet Прогноз (2)
E1: 45887 | F1: 45887 | J1: 45887 | L1: 45887 | N1: 45841 | O1: 45841 | P1: 45750 | T1: ensemble_best_config | U1: xgboost_iqr | V1: vecm | W1: var_iqr | X1: sarima_simple_iqr | Y1: sarima_simple | Z1: sarima_component_iqr | AA1: sarima_component | AB1: prophet_iqr | AC1: lstm_iqr | AD1: lstm | AE1: hybrid_var_xgb | AF1: favar_iqr | AG1: dfm_iqr | AH1: bvar | BD1: 45580 | BE1: 45580
A2: Дата | B2: -0.5 | E2: MoM | F2: YoY | G2: 1 вер mom | H2: 1 вер yoy | I2: 3mmasaar | J2: MoM_Old | K2: MoM разница | L2: YoY_Old | M2: YoY разница | N2: Ростов MoM New | O2: Ростов YoY New | P2: Ростов MoM | Q2: Ростов YoY | BC2: БР | BD2: Ростов + 1 нед октября
A3: 44562 | E3: 101.22 | F3: 108.84 | BD3: 44562 | BE3: 1.22 | BG3: 100 | BH3: =BE3+$BG$3 -> 101.22
A4: 44593 | E4: 100.94 | F4: 108.73 | BD4: 44593 | BE4: 0.94 | BH4: =BE4+$BG$3 -> 100.94
A5: 44621 | E5: 105.55 | F5: 113.29 | I5: =AVERAGE($E3:$E5)^12/100^11-100 -> 35.595184 | BD5: 44621 | BE5: 5.55 | BH5: =BE5+$BG$3 -> 105.55
A6: 44652 | E6: 103.28 | F6: 116 | I6: =AVERAGE($E4:$E6)^12/100^11-100 -> 46.89845 | BD6: 44652 | BE6: 3.28 | BH6: =BE6+$BG$3 -> 103.28
A7: 44682 | E7: 100.68 | F7: 116.31 | I7: =AVERAGE($E5:$E7)^12/100^11-100 -> 45.425701 | BD7: 44682 | BE7: 0.68 | BH7: =BE7+$BG$3 -> 100.68
A8: 44713 | E8: 99.32 | F8: 114.88 | I8: =AVERAGE($E6:$E8)^12/100^11-100 -> 13.938422 | BD8: 44713 | BE8: -0.68 | BH8: =BE8+$BG$3 -> 99.32
A9: 44743 | E9: 99.23 | F9: 113.75 | I9: =AVERAGE($E7:$E9)^12/100^11-100 -> -3.0368905 | BD9: 44743 | BE9: -0.77 | BH9: =BE9+$BG$3 -> 99.23
A10: 44774 | E10: 99.43 | F10: 112.92 | I10: =AVERAGE($E8:$E10)^12/100^11-100 -> -7.787386 | BD10: 44774 | BE10: -0.57 | BH10: =BE10+$BG$3 -> 99.43
A11: 44805 | E11: 100.33 | F11: 112.46 | I11: =AVERAGE($E9:$E11)^12/100^11-100 -> -3.9660258 | BD11: 44805 | BE11: 0.33 | BH11: =BE11+$BG$3 -> 100.33
A12: 44835 | E12: 100.66 | F12: 112.17 | I12: =AVERAGE($E10:$E12)^12/100^11-100 -> 1.6929966 | BD12: 44835 | BE12: 0.66 | BH12: =BE12+$BG$3 -> 100.66
A13: 44866 | E13: 100.26 | F13: 111.51 | I13: =AVERAGE($E11:$E13)^12/100^11-100 -> 5.1161898 | BD13: 44866 | BE13: 0.26 | BH13: =BE13+$BG$3 -> 100.26
A14: 44896 | E14: 100.57 | F14: 111.9 | I14: =AVERAGE($E12:$E14)^12/100^11-100 -> 6.1255331 | BD14: 44896 | BE14: 0.57 | BH14: =BE14+$BG$3 -> 100.57
A15: 44927 | E15: 101.13 | F15: 111.8 | I15: =AVERAGE($E13:$E15)^12/100^11-100 -> 8.1279436 | BD15: 44927 | BE15: 1.13 | BH15: =BE15+$BG$3 -> 101.13
A16: 44958 | E16: 100.75 | F16: 111.59 | I16: =AVERAGE($E14:$E16)^12/100^11-100 -> 10.252389 | K16: 0.09 | L16: 100 | M16: =K16+L16 -> 100.09 | BD16: 44958 | BE16: 0.75 | BH16: =BE16+$BG$3 -> 100.75
A17: 44986 | E17: 100.39 | F17: 106.14 | I17: =AVERAGE($E15:$E17)^12/100^11-100 -> 9.4675745 | K17: 0.62 | L17: 100 | M17: =K17+L17 -> 100.62 | BD17: 44986 | BE17: 0.39 | BH17: =BE17+$BG$3 -> 100.39
A18: 45017 | E18: 100.72 | F18: 103.51 | I18: =AVERAGE($E16:$E18)^12/100^11-100 -> 7.6990211 | BD18: 45017 | BE18: 0.72 | BH18: =BE18+$BG$3 -> 100.72
A19: 45047 | E19: 99.75 | F19: 102.55 | I19: =AVERAGE($E17:$E19)^12/100^11-100 -> 3.494759 | BD19: 45047 | BE19: -0.25 | BH19: =BE19+$BG$3 -> 99.75
A20: 45078 | E20: 100.43 | F20: 103.69 | I20: =AVERAGE($E18:$E20)^12/100^11-100 -> 3.659998 | BD20: 45078 | BE20: 0.43 | BH20: =BE20+$BG$3 -> 100.43
A21: 45108 | E21: 100.5 | F21: 105.03 | I21: =AVERAGE($E19:$E21)^12/100^11-100 -> 2.7541668 | BD21: 45108 | BE21: 0.5 | BH21: =BE21+$BG$3 -> 100.5
A22: 45139 | E22: 99.93 | F22: 105.56 | I22: =AVERAGE($E20:$E22)^12/100^11-100 -> 3.494759 | M22: =F22-L22 -> 105.56 | N22: =E22 -> 99.93 | BD22: 45139 | BE22: -0.07 | BH22: =BE22+$BG$3 -> 99.93
A23: 45170 | E23: 101.75 | F23: 107.05 | I23: =AVERAGE($E21:$E23)^12/100^11-100 -> 9.0770906 | M23: =F23-L23 -> 107.05 | N23: =E23 -> 101.75 | BD23: 45170 | BE23: 1.75 | BH23: =BE23+$BG$3 -> 101.75
A24: 45200 | B24: =E24-0.5 -> 99.96 | E24: 100.46 | F24: 106.84 | I24: =AVERAGE($E22:$E24)^12/100^11-100 -> 8.9039524 | M24: =F24-L24 -> 106.84 | BD24: 45200 | BE24: 0.46 | BH24: =BE24+$BG$3 -> 100.46
A25: 45231 | E25: 100.74 | F25: 107.34 | G25: 107.34 | I25: =AVERAGE($E23:$E25)^12/100^11-100 -> 12.459572 | M25: =F25-L25 -> 107.34 | BD25: 45231 | BE25: 0.74 | BH25: =BE25+$BG$3 -> 100.74
A26: 45261 | E26: 100.29 | F26: 107.05 | G26: 100.29 | I26: =AVERAGE($E24:$E26)^12/100^11-100 -> 6.1255331 | M26: =F26-L26 -> 107.05 | BD26: 45261 | BE26: 0.29 | BH26: =BE26+$BG$3 -> 100.29
A27: 45292 | E27: 100.87 | F27: 106.77 | G27: 100.87 | I27: =AVERAGE($E25:$E27)^12/100^11-100 -> 7.8704026 | BD27: 45292 | BE27: 0.87 | BH27: =BE27+$BG$3 -> 100.87
A28: 45323 | E28: 100.53 | F28: 106.54 | G28: 100.53 | I28: =AVERAGE($E26:$E28)^12/100^11-100 -> 6.9734306 | BD28: 45323 | BE28: 0.53 | BH28: =BE28+$BG$3 -> 100.53
A29: 45352 | E29: 100.53 | F29: 106.68 | G29: 100.53 | I29: =AVERAGE($E27:$E29)^12/100^11-100 -> 7.9991028 | BD29: 45352 | BE29: 0.53 | BH29: =BE29+$BG$3 -> 100.53
A30: 45383 | E30: 100.38 | F30: 106.32 | G30: 100.38 | I30: =AVERAGE($E28:$E30)^12/100^11-100 -> 5.9145235 | BD30: 45383 | BE30: 0.38 | BH30: =BE30+$BG$3 -> 100.38
A31: 45413 | E31: 100.94 | F31: 107.59 | G31: 100.94 | I31: =AVERAGE($E29:$E31)^12/100^11-100 -> 7.6562147 | BD31: 45413 | BE31: 0.94 | BH31: =BE31+$BG$3 -> 100.94
A32: 45444 | E32: 100.18 | F32: 107.33 | G32: 100.18 | I32: =AVERAGE($E30:$E32)^12/100^11-100 -> 6.1677812 | P32: 99.994219 | Q32: 106.07036 | R32: 106.01112 | T32: 100.18 | U32: 100.18 | V32: 100.18 | W32: 100.18 | X32: 100.18 | Y32: 100.18 | Z32: 100.18 | AA32: 100.18 | AB32: 100.18 | AC32: 100.18 | AD32: 100.18 | AE32: 100.18 | AF32: 100.18 | AG32: 100.18 | AH32: 100.18 | BD32: 45444 | BE32: 0.18 | BH32: =BE32+$BG$3 -> 100.18
A33: 45474 | E33: 101.07 | F33: 107.94 | G33: 101.07 | I33: =AVERAGE($E31:$E33)^12/100^11-100 -> 9.1204146 | K33: =E33-J33 -> 101.07 | P33: 100.72 | Q33: 106.77127 | R33: 104.91752 | T33: 101.07 | U33: 101.07 | V33: 101.07 | W33: 101.07 | X33: 101.07 | Y33: 101.07 | Z33: 101.07 | AA33: 101.07 | AB33: 101.07 | AC33: 101.07 | AD33: 101.07 | AE33: 101.07 | AF33: 101.07 | AG33: 101.07 | AH33: 101.07 | BD33: 45474 | BE33: 1.07 | BH33: =BE33+$BG$3 -> 101.07
A34: 45505 | E34: 100.09 | F34: 108.1 | G34: 100.09 | I34: =AVERAGE($E32:$E34)^12/100^11-100 -> 5.4936577 | K34: =E34-J34 -> 100.09 | P34: 100.01719 | Q34: 106.86443 | R34: 105.264 | T34: 100.09 | U34: 100.09 | V34: 100.09 | W34: 100.09 | X34: 100.09 | Y34: 100.09 | Z34: 100.09 | AA34: 100.09 | AB34: 100.09 | AC34: 100.09 | AD34: 100.09 | AE34: 100.09 | AF34: 100.09 | AG34: 100.09 | AH34: 100.09 | BD34: 45505 | BE34: 0.09 | BH34: =BE34+$BG$3 -> 100.09
A35: 45536 | E35: 100.62 | F35: 106.91 | G35: 100.62 | I35: =AVERAGE($E33:$E35)^12/100^11-100 -> 7.3570066 | K35: =E35-J35 -> 100.62 | N35: 100.62 | P35: 100.59467 | Q35: 106.90435 | R35: 104.72241 | T35: 100.62 | U35: 100.62 | V35: 100.62 | W35: 100.62 | X35: 100.62 | Y35: 100.62 | Z35: 100.62 | AA35: 100.62 | AB35: 100.62 | AC35: 100.62 | AD35: 100.62 | AE35: 100.62 | AF35: 100.62 | AG35: 100.62 | AH35: 100.62 | BD35: 45536 | BE35: 0.62 | BH35: =BE35+$BG$3 -> 100.62
A36: 45566 | B36: =E36-0.5 -> 100.52 | E36: 101.02 | F36: 107.49 | G36: 101.02 | I36: =AVERAGE($E34:$E36)^12/100^11-100 -> 7.1437535 | J36: 101.02 | K36: =E36-J36 -> 0 | L36: 107.49 | M36: =F36-L36 -> 0 | N36: 101.02 | P36: 100.48289 | Q36: 106.92871 | R36: 104.56424 | T36: 101.02 | U36: 101.02 | V36: 101.02 | W36: 101.02 | X36: 101.02 | Y36: 101.02 | Z36: 101.02 | AA36: 101.02 | AB36: 101.02 | AC36: 101.02 | AD36: 101.02 | AE36: 101.02 | AF36: 101.02 | AG36: 101.02 | AH36: 101.02
A37: 45597 | B37: =E37-0.5 -> 101 | E37: 101.5 | F37: 108.31 | G37: 101.5 | I37: =AVERAGE($E35:$E37)^12/100^11-100 -> 13.308867 | J37: 101.5 | K37: =E37-J37 -> 0 | L37: 108.31 | M37: =F37-L37 -> 0 | N37: 101.5 | P37: 101.36349 | Q37: 108.16549 | R37: 104.00077 | T37: 101.5 | U37: 101.5 | V37: 101.5 | W37: 101.5 | X37: 101.5 | Y37: 101.5 | Z37: 101.5 | AA37: 101.5 | AB37: 101.5 | AC37: 101.5 | AD37: 101.5 | AE37: 101.5 | AF37: 101.5 | AG37: 101.5 | AH37: 101.5
A38: 45627 | E38: 100.91 | F38: 108.98 | G38: 100.91 | I38: =AVERAGE($E36:$E38)^12/100^11-100 -> 14.616502 | J38: 100.91 | K38: =E38-J38 -> 0 | L38: 108.98 | M38: =F38-L38 -> 0 | N38: 100.91 | P38: 100.55262 | Q38: 108.44873 | R38: 103.81599 | T38: 100.91 | U38: 100.91 | V38: 100.91 | W38: 100.91 | X38: 100.91 | Y38: 100.91 | Z38: 100.91 | AA38: 100.91 | AB38: 100.91 | AC38: 100.91 | AD38: 100.91 | AE38: 100.91 | AF38: 100.91 | AG38: 100.91 | AH38: 100.91 | BC38: 4-4,5
A39: 45658 | E39: 100.84 | F39: 108.95 | G39: 100.65 | H39: =ROUND(PRODUCT(G28:G39)/100^11,2) -> 108.74 | I39: =AVERAGE($E37:$E39)^12/100^11-100 -> 13.803248 | J39: 100.84 | L39: 108.95 | M39: =F39-L39 -> 0 | N39: 100.84 | P39: 101.43 | Q39: 109.59 | T39: 100.84 | U39: 100.84 | V39: 100.84 | W39: 100.84 | X39: 100.84 | Y39: 100.84 | Z39: 100.84 | AA39: 100.84 | AB39: 100.84 | AC39: 100.84 | AD39: 100.84 | AE39: 100.84 | AF39: 100.84 | AG39: 100.84 | AH39: 100.84
A40: 45689 | E40: 101.34 | F40: 109.83 | G40: 100.5 | H40: =ROUND(PRODUCT(G29:G40)/100^11,2) -> 108.71 | I40: =AVERAGE($E38:$E40)^12/100^11-100 -> 13.0848 | J40: 101.34 | K40: =E40-J40 -> 0 | L40: 109.83 | M40: =F40-L40 -> 0 | N40: 101.34 | P40: 100.84936 | Q40: 109.29444 | T40: 101.34 | U40: 101.34 | V40: 101.34 | W40: 101.34 | X40: 101.34 | Y40: 101.34 | Z40: 101.34 | AA40: 101.34 | AB40: 101.34 | AC40: 101.34 | AD40: 101.34 | AE40: 101.34 | AF40: 101.34 | AG40: 101.34 | AH40: 101.34
...

Sheet РасчетSaar
A1: Date | B1: MoM | C1: MoMF | D1: IPC_BASE | E1: YoY | F1: IPC_BASE_SA | G1: IPC_BASE_SA 2 IPC SA | H1: 3MMASAAR | I1: YoYSA | J1: ВВГУ MomSA | K1: ВВГУ 3mmsaar
A2: 40148 | D2: 100 | F2: 101.37736
A3: 40179 | B3: 1.49 | C3: =B3+100 -> 101.49 | D3: =C3*D2/100 -> 101.49 | E3: 108.84 | F3: 102.33624 | G3: =F3/F2*100 -> 100.94585
A4: 40210 | B4: 1.2 | C4: =B4+100 -> 101.2 | D4: =C4*D3/100 -> 102.70788 | E4: 109.21 | F4: 103.07799 | G4: =F4/F3*100 -> 100.72482
A5: 40238 | B5: 0.92 | C5: =B5+100 -> 100.92 | D5: =C5*D4/100 -> 103.65279 | E5: 108.98 | F5: 103.55137 | G5: =F5/F4*100 -> 100.45924 | H5: =AVERAGE(G3:G5)^12/100^11-100 -> 8.8603197
A6: 40269 | B6: 0.59 | C6: =B6+100 -> 100.59 | D6: =C6*D5/100 -> 104.26434 | E6: 108.04 | F6: 104.20609 | G6: =F6/F5*100 -> 100.63227 | H6: =AVERAGE(G4:G6)^12/100^11-100 -> 7.5121996
A7: 40299 | B7: 0.64 | C7: =B7+100 -> 100.64 | D7: =C7*D6/100 -> 104.93164 | E7: 108.11 | F7: 105.43867 | G7: =F7/F6*100 -> 101.18283 | H7: =AVERAGE(G5:G7)^12/100^11-100 -> 9.4864175
A8: 40330 | B8: 0.73 | C8: =B8+100 -> 100.73 | D8: =C8*D7/100 -> 105.69764 | E8: 107.36 | F8: 105.33045 | G8: =F8/F7*100 -> 99.897361 | H8: =AVERAGE(G6:G8)^12/100^11-100 -> 7.0690291
A9: 40360 | B9: -0.49 | C9: =B9+100 -> 99.51 | D9: =C9*D8/100 -> 105.17972 | E9: 106.82 | F9: 106.42573 | G9: =F9/F8*100 -> 101.03985 | H9: =AVERAGE(G7:G9)^12/100^11-100 -> 8.8176521
A10: 40391 | B10: 0.48 | C10: =B10+100 -> 100.48 | D10: =C10*D9/100 -> 105.68458 | E10: 106.83 | F10: 108.68682 | G10: =F10/F9*100 -> 102.12458 | H10: =AVERAGE(G8:G10)^12/100^11-100 -> 12.958558
A11: 40422 | B11: 2.29 | C11: =B11+100 -> 102.29 | D11: =C11*D10/100 -> 108.10476 | E11: 109.12 | F11: 109.24047 | G11: =F11/F10*100 -> 100.5094 | H11: =AVERAGE(G9:G11)^12/100^11-100 -> 15.726627
A12: 40452 | B12: 0.5 | C12: =B12+100 -> 100.5 | D12: =C12*D11/100 -> 108.64528 | E12: 109.47 | F12: 110.21359 | G12: =F12/F11*100 -> 100.8908 | H12: =AVERAGE(G10:G12)^12/100^11-100 -> 15.04685
A13: 40483 | B13: 0.92 | C13: =B13+100 -> 100.92 | D13: =C13*D12/100 -> 109.64482 | E13: 109.96 | F13: 111.62215 | G13: =F13/F12*100 -> 101.27803 | H13: =AVERAGE(G11:G13)^12/100^11-100 -> 11.25489
A14: 40513 | B14: 1.57 | C14: =B14+100 -> 101.57 | D14: =C14*D13/100 -> 111.36624 | E14: 111.36 | F14: 113.9164 | G14: =F14/F13*100 -> 102.05538 | H14: =AVERAGE(G12:G14)^12/100^11-100 -> 18.268772
A15: 40544 | B15: 2.4 | C15: =B15+100 -> 102.4 | D15: =C15*D14/100 -> 114.03903 | E15: 112.36 | F15: 114.83955 | G15: =F15/F14*100 -> 100.81038 | H15: =AVERAGE(G13:G15)^12/100^11-100 -> 17.894124
A16: 40575 | B16: 1.06 | C16: =B16+100 -> 101.06 | D16: =C16*D15/100 -> 115.24785 | E16: 112.21 | F16: 115.90163 | G16: =F16/F15*100 -> 100.92483 | H16: =AVERAGE(G14:G16)^12/100^11-100 -> 16.261694
... A74: 42339 | B74: 0.62 | C74: =B74+100 -> 100.62 | D74: =C74*D73/100 -> 173.7165 | E74: 115.3 | F74: 174.94446 | G74: =F74/F73*100 -> 100.50612 | H74: =AVERAGE(G72:G74)^12/100^11-100 -> 4.5422559
A75: 42370 | B75: 0.79 | C75: =B75+100 -> 100.79 | D75: =C75*D74/100 -> 175.08886 | E75: 111.62 | F75: 175.63775 | G75: =F75/F74*100 -> 100.39629 | H75: =AVERAGE(G73:G75)^12/100^11-100 -> 5.0390613 | J75: 100.31
A76: 42401 | B76: 0.62 | C76: =B76+100 -> 100.62 | D76: =C76*D75/100 -> 176.17441 | E76: 109.03 | F76: 175.76371 | G76: =F76/F75*100 -> 100.07172 | H76: =AVERAGE(G74:G76)^12/100^11-100 -> 3.9668762 | J76: 100.27
A77: 42430 | B77: 0.25 | C77: =B77+100 -> 100.25 | D77: =C77*D76/100 -> 176.61485 | E77: 107.24 | F77: 177.27679 | G77: =F77/F76*100 -> 100.86086 | H77: =AVERAGE(G75:G77)^12/100^11-100 -> 5.4468942 | J77: 100.03 | K77: =AVERAGE(J75:J77)^12/100^11-100 -> 2.4674731
A78: 42461 | B78: 1.09 | C78: =B78+100 -> 101.09 | D78: =C78*D77/100 -> 178.53995 | E78: 107.08 | F78: 177.73055 | G78: =F78/F77*100 -> 100.25596 | H78: =AVERAGE(G76:G78)^12/100^11-100 -> 4.8591174 | J78: 101 | K78: =AVERAGE(J76:J78)^12/100^11-100 -> 5.3257411
A79: 42491 | B79: 0.21 | C79: =B79+100 -> 100.21 | D79: =C79*D78/100 -> 178.91488 | E79: 106.91 | F79: 178.86088 | G79: =F79/F78*100 -> 100.63598 | H79: =AVERAGE(G77:G79)^12/100^11-100 -> 7.2409473 | J79: 100.26 | K79: =AVERAGE(J77:J79)^12/100^11-100 -> 5.2838002
A80: 42522 | B80: 0.24 | C80: =B80+100 -> 100.24 | D80: =C80*D79/100 -> 179.34428 | E80: 107.47 | F80: 180.56225 | G80: =F80/F79*100 -> 100.95123 | H80: =AVERAGE(G78:G80)^12/100^11-100 -> 7.6269764 | J80: 100.43 | K80: =AVERAGE(J78:J80)^12/100^11-100 -> 6.9734306
A81: 42552 | B81: 0.61 | C81: =B81+100 -> 100.61 | D81: =C81*D80/100 -> 180.43828 | E81: 107.77 | F81: 181.70127 | G81: =F81/F80*100 -> 100.63082 | H81: =AVERAGE(G79:G81)^12/100^11-100 -> 9.2419243 | J81: 101.03 | K81: =AVERAGE(J79:J81)^12/100^11-100 -> 7.1011495
A82: 42583 | B82: 0.09 | C82: =B82+100 -> 100.09 | D82: =C82*D81/100 -> 180.60067 | E82: 107.39 | F82: 181.48653 | G82: =F82/F81*100 -> 99.881813 | H82: =AVERAGE(G80:G82)^12/100^11-100 -> 6.0151694 | J82: 100.56 | K82: =AVERAGE(J80:J82)^12/100^11-100 -> 8.3860482
A83: 42614 | B83: -0.13 | C83: =B83+100 -> 99.87 | D83: =C83*D82/100 -> 180.36589 | E83: 106.18 | F83: 182.43603 | G83: =F83/F82*100 -> 100.52318 | H83: =AVERAGE(G81:G83)^12/100^11-100 -> 4.2228616 | J83: 100.24 | K83: =AVERAGE(J81:J83)^12/100^11-100 -> 7.5706488
A84: 42644 | B84: 0.6 | C84: =B84+100 -> 100.6 | D84: =C84*D83/100 -> 181.44809 | E84: 105.43 | F84: 182.86692 | G84: =F84/F83*100 -> 100.23619 | H84: =AVERAGE(G82:G84)^12/100^11-100 -> 2.5950908 | J84: 100.56 | K84: =AVERAGE(J82:J84)^12/100^11-100 -> 5.577708
A85: 42675 | B85: 0.29 | C85: =B85+100 -> 100.29 | D85: =C85*D84/100 -> 181.97429 | E85: 105.39 | F85: 184.77573 | G85: =F85/F84*100 -> 101.04383 | H85: =AVERAGE(G83:G85)^12/100^11-100 -> 7.4560683 | J85: 100.16 | K85: =AVERAGE(J83:J85)^12/100^11-100 -> 3.9083101
A86: 42705 | B86: 1.33 | C86: =B86+100 -> 101.33 | D86: =C86*D85/100 -> 184.39454 | E86: 106.13 | F86: 185.10631 | G86: =F86/F85*100 -> 100.17891 | H86: =AVERAGE(G84:G86)^12/100^11-100 -> 5.9943268 | J86: 101.04 | K86: =AVERAGE(J84:J86)^12/100^11-100 -> 7.2716587
A87: 42736 | B87: 0.47 | C87: =B87+100 -> 100.47 | D87: =C87*D86/100 -> 185.2612 | E87: 105.79 | F87: 185.29478 | G87: =F87/F86*100 -> 100.10182 | H87: =AVERAGE(G85:G87)^12/100^11-100 -> 5.4287806 | J87: 100.04 | K87: =AVERAGE(J85:J87)^12/100^11-100 -> 5.0743254
A88: 42767 | B88: 0.33 | C88: =B88+100 -> 100.33 | D88: =C88*D87/100 -> 185.87256 | E88: 105.49 | F88: 185.35257 | G88: =F88/F87*100 -> 100.03119 | H88: =AVERAGE(G86:G88)^12/100^11-100 -> 1.2548031 | J88: 99.97 | K88: =AVERAGE(J86:J88)^12/100^11-100 -> 4.2818007
... A166: 45139 | B166: -0.07 | C166: =B166+100 -> 99.93 | D166: =C166*D165/100 -> 268.02841 | E166: 105.56 | F166: 274.44913 | G166: =F166/F165*100 -> 101.65122 | H166: =AVERAGE(G164:G166)^12/100^11-100 -> 12.665468 | J166: 100.62 | K166: =AVERAGE(J164:J166)^12/100^11-100 -> 12.014922
A167: 45170 | B167: 1.75 | C167: =B167+100 -> 101.75 | D167: =C167*D166/100 -> 272.71891 | E167: 107.05 | F167: 275.26515 | G167: =F167/F166*100 -> 100.29733 | H167: =AVERAGE(G165:G167)^12/100^11-100 -> 10.34479 | J167: 102.01 | K167: =AVERAGE(J165:J167)^12/100^11-100 -> 17.597807 | O167: 44256 | P167: 44896 | Q167: 44986 | R167: 45078 | S167: 45170 | T167: 45261 | U167: 45352 | V167: 45444 | W167: 45536 | X167: 45627 | Y167: 45717 | Z167: 45809 | AA167: 45901 | AB167: 45992 | AC167: 46082 | AD167: 46174 | AE167: 46266 | AF167: 46357 | AG167: 46447 | AH167: 46539 | AI167: 46631 | AJ167: 46722
A168: 45200 | B168: 0.46 | C168: =B168+100 -> 100.46 | D168: =C168*D167/100 -> 273.97342 | E168: 106.84 | F168: 277.04336 | G168: =F168/F167*100 -> 100.646 | H168: =AVERAGE(G166:G168)^12/100^11-100 -> 10.886393 | J168: 100.32 | K168: =AVERAGE(J166:J168)^12/100^11-100 -> 12.459572 | O168: 2021 | Q168: 2023 | U168: 2024 | Y168: 2025 | AC168: 2026 | AG168: 2027
A169: 45231 | B169: 0.74 | C169: =B169+100 -> 100.74 | D169: =C169*D168/100 -> 276.00082 | E169: 107.34 | F169: 277.60789 | G169: =F169/F168*100 -> 100.20377 | H169: =AVERAGE(G167:G169)^12/100^11-100 -> 4.6861335 | I169: =AVERAGE(G158:G169)^12/100^11-100 -> 7.0512472 | J169: 100.36 | K169: =AVERAGE(J167:J169)^12/100^11-100 -> 11.306832 | O169: I кв. | P169: IV кв. | Q169: I кв. | R169: II кв. | S169: III кв. | T169: IV кв. | U169: I кв. | V169: II кв. | W169: III кв. | X169: IV кв. | Y169: I кв. | Z169: II кв. | AA169: III кв. | AB169: IV кв. | AC169: I кв. | AD169: II кв. | AE169: III кв. | AF169: IV кв. | AG169: I кв. | AH169: II кв. | AI169: III кв. | AJ169: IV кв.
A170: 45261 | B170: 0.29 | C170: =B170+100 -> 100.29 | D170: =C170*D169/100 -> 276.80122 | E170: 107.05 | F170: 278.83822 | G170: =F170/F169*100 -> 100.44319 | H170: =AVERAGE(G168:G170)^12/100^11-100 -> 5.2962003 | I170: =AVERAGE(G159:G170)^12/100^11-100 -> 6.7629817 | J170: 100.23 | K170: =AVERAGE(J168:J170)^12/100^11-100 -> 3.7013456 | N170: 3MMASAAR | O170: =SUMIFS($K$5:$K$206,$A$5:$A$206,O$167) -> 6.5911112 | P170: =SUMIFS($K$5:$K$206,$A$5:$A$206,P$167) -> 2.9183218 | Q170: =SUMIFS($K$5:$K$206,$A$5:$A$206,Q$167) -> 4.0741543 | R170: =SUMIFS($K$5:$K$206,$A$5:$A$206,R$167) -> 4.6982333 | S170: =SUMIFS($K$5:$K$206,$A$5:$A$206,S$167) -> 17.597807 | T170: =SUMIFS($K$5:$K$206,$A$5:$A$206,T$167) -> 3.7013456 | U170: =SUMIFS($K$5:$K$206,$A$5:$A$206,U$167) -> 2.6312082 | V170: =SUMIFS($K$5:$K$206,$A$5:$A$206,V$167) -> 7.1437535 | ... AF170: =SUMIFS($K$5:$K$206,$A$5:$A$206,AF$167) -> 4.1819232 | AG170: =SUMIFS($K$5:$K$218,$A$5:$A$218,AG$167) -> 4.1585964 | AH170: =SUMIFS($K$5:$K$218,$A$5:$A$218,AH$167) -> 5.0211404 | AI170: =SUMIFS($K$5:$K$218,$A$5:$A$218,AI$167) -> 4.5472891 | AJ170: =SUMIFS($K$5:$K$218,$A$5:$A$218,AJ$167) -> 1.948566
A171: 45292 | B171: 0.87 | C171: =B171+100 -> 100.87 | D171: =C171*D170/100 -> 279.20939 | E171: 106.77 | F171: 279.42434 | G171: =F171/F170*100 -> 100.2102 | H171: =AVERAGE(G169:G171)^12/100^11-100 -> 3.4830317 | I171: =AVERAGE(G160:G171)^12/100^11-100 -> 6.5191623 | J171: 100.36 | K171: =AVERAGE(J169:J171)^12/100^11-100 -> 3.8668869 | N171: YoY | O171: =IF(SUMIFS($E$5:$E$206,$A$5:$A$206,O$167)>90,SUMIFS($E$5:$E$206,$A$5:$A$206,O$167)-100,SUMIFS($E$5:$E$206,$A$5:$A$206,O$167)) -> 6.83 | P171: =IF(SUMIFS($E$5:$E$206,$A$5:$A$206,P$167)>90,SUMIFS($E$5:$E$206,$A$5:$A$206,P$167)-100,SUMIFS($E$5:$E$206,$A$5:$A$206,P$167)) -> 11.9 | Q171: =IF(SUMIFS($E$5:$E$206,$A$5:$A$206,Q$167)>90,SUMIFS($E$5:$E$206,$A$5:$A$206,Q$167)-100,SUMIFS($E$5:$E$206,$A$5:$A$206,Q$167)) -> 6.14 | R171: =IF(SUMIFS($E$5:$E$206,$A$5:$A$206,R$167)>90,SUMIFS($E$5:$E$206,$A$5:$A$206,R$167)-100,SUMIFS($E$5:$E$206,$A$5:$A$206,R$167)) -> 3.69 | S171: =IF(SUMIFS($E$5:$E$206,$A$5:$A$206,S$167)>90,SUMIFS($E$5:$E$206,$A$5:$A$206,S$167)-100,SUMIFS($E$5:$E$206,$A$5:$A$206,S$167)) -> 7.05 | T171: =IF(SUMIFS($E$5:$E$206,$A$5:$A$206,T$167)>90,SUMIFS($E$5:$E$206,$A$5:$A$206,T$167)-100,SUMIFS($E$5:$E$206,$A$5:$A$206,T$167)) -> 7.05 | U171: =IF(SUMIFS($E$5:$E$206,$A$5:$A$206,U$167)>90,SUMIFS($E$5:$E$206,$A$5:$A$206,U$167)-100,SUMIFS($E$5:$E$206,$A$5:$A$206,U$167)) -> 6.68 | V171: =IF(SUMIFS($E$5:$E$206,$A$5:$A$206,V$167)>90,SUMIFS($E$5:$E$206,$A$5:$A$206,V$167)-100,SUMIFS($E$5:$E$206,$A$5:$A$206,V$167)) -> 7.33 | ... AF171: =IF(SUMIFS($E$5:$E$206,$A$5:$A$206,AF$167)>90,SUMIFS($E$5:$E$206,$A$5:$A$206,AF$167)-100,SUMIFS($E$5:$E$206,$A$5:$A$206,AF$167)) -> 5.63 | AG171: =IF(SUMIFS($E$5:$E$218,$A$5:$A$218,AG$167)>90,SUMIFS($E$5:$E$218,$A$5:$A$218,AG$167)-100,SUMIFS($E$5:$E$218,$A$5:$A$218,AG$167)) -> 4.45 | AH171: =IF(SUMIFS($E$5:$E$218,$A$5:$A$218,AH$167)>90,SUMIFS($E$5:$E$218,$A$5:$A$218,AH$167)-100,SUMIFS($E$5:$E$218,$A$5:$A$218,AH$167)) -> 5.11 | AI171: =IF(SUMIFS($E$5:$E$218,$A$5:$A$218,AI$167)>90,SUMIFS($E$5:$E$218,$A$5:$A$218,AI$167)-100,SUMIFS($E$5:$E$218,$A$5:$A$218,AI$167)) -> 5.37 | AJ171: =IF(SUMIFS($E$5:$E$218,$A$5:$A$218,AJ$167)>90,SUMIFS($E$5:$E$218,$A$5:$A$218,AJ$167)-100,SUMIFS($E$5:$E$218,$A$5:$A$218,AJ$167)) -> 4.02
A172: 45323 | B172: 0.53 | C172: =Прогноз!E28 -> 100.53 | D172: =C172*D171/100 -> 280.6892 | E172: 106.54 | F172: 280.45667 | G172: =F172/F171*100 -> 100.36945 | H172: =AVERAGE(G170:G172)^12/100^11-100 -> 4.1689565 | I172: =AVERAGE(G161:G172)^12/100^11-100 -> 6.6757115 | J172: 100.09 | K172: =AVERAGE(J170:J172)^12/100^11-100 -> 2.7541668
A173: 45352 | B173: 0.53 | C173: =Прогноз!E29 -> 100.53 | D173: =C173*D172/100 -> 282.17686 | E173: 106.68 | F173: 281.22829 | G173: =F173/F172*100 -> 100.27513 | H173: =AVERAGE(G171:G173)^12/100^11-100 -> 3.4732115 | I173: =AVERAGE(G162:G173)^12/100^11-100 -> 6.3495329 | J173: 100.2 | K173: =AVERAGE(J171:J173)^12/100^11-100 -> 2.6312082
A174: 45383 | C174: =Прогноз!E30 -> 100.38 | D174: =C174*D173/100 -> 283.24913 | E174: 106.32 | F174: 284.3441 | G174: =F174/F173*100 -> 101.10793 | H174: =AVERAGE(G172:G174)^12/100^11-100 -> 7.2397015 | I174: =AVERAGE(G163:G174)^12/100^11-100 -> 7.6317453 | J174: 100.26 | K174: =AVERAGE(J172:J174)^12/100^11-100 -> 2.2223195
...

Sheet Корректировки

Sheet Описания
A1: Дата
A2: MoM | B2: Прогнозный МоМ
A3: Прогнозный YoY

Sheet Параметры
A1: Значение
A2: {=MID(CELL("filename",A1),1,SEARCH("[",CELL("filename",A1))-1)&"IPC.xlsx"} -> C:\ЦБ_Работа\04_Прогноз\_1_Прогноз\_Актуальный прогноз\2026\062026\IPC.xlsx

Sheet Лист1
A1: Day | B1: YoY | C1: MoM | I1: Day | J1: YoY | K1: MoM | L1: Столбец1 | P1: dnd
A2: 40269 | B2: 8.04 | C2: 0.59 | I2: 40179 | J2: 8.84 | K2: 1.49 | Q2: Seasonally adjusted
A3: 40634 | B3: 12.45 | C3: 0.6 | I3: 40210 | J3: 9.21 | K3: 1.2 | P3: 40148 | Q3: 100.24335
A4: 41000 | B4: 3.89 | C4: 0.42 | I4: 40238 | J4: 8.98 | K4: 0.92 | P4: 40179 | Q4: 101.4075
A5: 41365 | B5: 9.34 | C5: 1.25 | I5: 40269 | J5: 8.04 | K5: 0.59 | P5: 40210 | Q5: 102.39394
A6: 41730 | B6: 6.82 | C6: 0.63 | I6: 40299 | J6: 8.11 | K6: 0.64 | P6: 40238 | Q6: 103.15606
A7: 42095 | B7: 17.22 | C7: 1.24 | I7: 40330 | J7: 7.36 | K7: 0.73 | P7: 40269 | Q7: 103.55263
A8: 42461 | B8: 7.08 | C8: 1.09 | I8: 40360 | J8: 6.82 | K8: -0.49 | P8: 40299 | Q8: 104.21708
A9: 42826 | B9: 5.11 | C9: 0.77 | I9: 40391 | J9: 6.83 | K9: 0.48 | P9: 40330 | Q9: 105.40698
A10: 43191 | B10: 1.58 | C10: 0.5 | I10: 40422 | J10: 9.12 | K10: 2.29 | P10: 40360 | Q10: 105.23083
A11: 43556 | B11: 5.65 | C11: 0.59 | I11: 40452 | J11: 9.47 | K11: 0.5 | P11: 40391 | Q11: 106.32149
A12: 43922 | B12: 3.57 | C12: 1.3 | I12: 40483 | J12: 9.96 | K12: 0.92 | P12: 40422 | Q12: 108.73519
A13: 44287 | B13: 6.37 | C13: 0.86 | I13: 40513 | J13: 11.36 | K13: 1.57 | P13: 40452 | Q13: 109.25882
A14: 44652 | B14: 16 | C14: 3.28 | I14: 40544 | J14: 12.36 | K14: 2.4 | P14: 40483 | Q14: 110.18349
A15: 45017 | B15: 3.51 | C15: 0.72 | I15: 40575 | J15: 12.21 | K15: 1.06 | P15: 40513 | Q15: 111.63598
A16: 45383 | B16: 6.32 | C16: 0.38 | E16: Средн | I16: 40603 | J16: 12.43 | K16: 1.12 | P16: 40544 | Q16: 113.94881
E17: =AVERAGE(Таблица1[MoM]) -> 0.948 | F17: =AVERAGEIF(Таблица1[MoM],"<2",Таблица1[MoM]) -> 0.78142857 | I17: 40634 | J17: 12.45 | K17: 0.6 | P17: 40575 | Q17: 114.8991
I18: 40664 | J18: 12.08 | K18: 0.31 | P18: 40603 | Q18: 115.98362
I19: 40695 | J19: 10.59 | K19: -0.61 | P19: 40634 | Q19: 116.43787
I20: 40725 | J20: 11.1 | K20: -0.04 | P20: 40664 | Q20: 116.79926
I21: 40756 | J21: 10.37 | K21: -0.18 | P21: 40695 | Q21: 116.56154
I22: 40787 | J22: 8.74 | K22: 0.78 | P22: 40725 | Q22: 116.88623
I23: 40817 | J23: 8.56 | K23: 0.33 | P23: 40756 | Q23: 117.3221
I24: 40848 | J24: 8.07 | K24: 0.46 | P24: 40787 | Q24: 118.22218
I25: 40878 | J25: 6.74 | K25: 0.32 | P25: 40817 | Q25: 118.58727
I26: 40909 | J26: 4.58 | K26: 0.33 | P26: 40848 | Q26: 119.04445
I27: 40940 | J27: 4.53 | K27: 1.02 | P27: 40878 | Q27: 119.13195
I28: 40969 | J28: 4.08 | K28: 0.68 | P28: 40909 | Q28: 119.15198
I29: 41000 | J29: 3.89 | K29: 0.42 | P29: 40940 | Q29: 120.10058
... I35: 41183 | J35: 7.93 | K35: 0.46 | P35: 41122 | Q35: 126.90935
I36: 41214 | J36: 8.18 | K36: 0.7 | L36: =AVERAGE(K33:K35) -> 0.32 | P36: 41153 | Q36: 127.43757
I37: 41244 | J37: 8.75 | K37: 0.84 | L37: =AVERAGE(K34:K36) -> 0.52666667 | P37: 41183 | Q37: 127.99159
I38: 41275 | J38: 9.19 | K38: 0.74 | L38: =AVERAGE(K35:K37) -> 0.66666667 | P38: 41214 | Q38: 128.79003
I39: 41306 | J39: 8.64 | K39: 0.51 | L39: =AVERAGE(K36:K38) -> 0.76 | P39: 41244 | Q39: 129.5532
I40: 41334 | J40: 8.45 | K40: 0.5 | L40: =AVERAGE(K37:K39) -> 0.69666667 | P40: 41275 | Q40: 130.11403
I41: 41365 | J41: 9.34 | K41: 1.25 | L41: =AVERAGE(K38:K40) -> 0.58333333 | P41: 41306 | Q41: 130.49122
I42: 41395 | J42: 9.47 | K42: 1.44 | L42: =AVERAGE(K39:K41) -> 0.75333333 | P42: 41334 | Q42: 130.91645
I43: 41426 | J43: 8.97 | K43: 0.09 | L43: =AVERAGE(K40:K42) -> 1.0633333 | P43: 41365 | Q43: 132.26416
I44: 41456 | J44: 7.87 | K44: 0.58 | L44: =AVERAGE(K41:K43) -> 0.92666667 | P44: 41395 | Q44: 134.16697
I45: 41487 | J45: 7.38 | K45: -0.38 | L45: =AVERAGE(K42:K44) -> 0.70333333 | P45: 41426 | Q45: 134.83081
...

Sheet for_sa
A1: Date | B1: IPC_BASE
A2: 40148 | B2: 100
A3: 40179 | B3: 101.49 | F3: 40148 | G3: 100.24389
A4: 40210 | B4: 102.70788 | F4: 40179 | G4: 101.42071
A5: 40238 | B5: 103.65279 | F5: 40210 | G5: 102.41014
A6: 40269 | B6: 104.26434 | F6: 40238 | G6: 103.1774
A7: 40299 | B7: 104.93164 | F7: 40269 | G7: 103.56485
A8: 40330 | B8: 105.69764 | F8: 40299 | G8: 104.2261
A9: 40360 | B9: 105.17972 | F9: 40330 | G9: 105.39896
A10: 40391 | B10: 105.68458 | F10: 40360 | G10: 105.221
A11: 40422 | B11: 108.10476 | F11: 40391 | G11: 106.2937
A12: 40452 | B12: 108.64528 | F12: 40422 | G12: 108.73084
A13: 40483 | B13: 109.64482 | F13: 40452 | G13: 109.24824
A14: 40513 | B14: 111.36624 | F14: 40483 | G14: 110.16693
... A206: 46357 | B206: 335.86595 | F206: 46327 | G206: 335.82118
F207: 46357 | G207: 336.69682
F208: 46388 | G208: 338.31296
F209: 46419 | G209: 340.15779
F210: 46447 | G210: 342.01267
F211: 46478 | G211: 343.87767
F212: 46508 | G212: 345.75284
F213: 46539 | G213: 347.63824
F214: 46569 | G214: 349.53391
F215: 46600 | G215: 351.43993
F216: 46631 | G216: 353.35634
F217: 46661 | G217: 355.28319
F218: 46692 | G218: 357.22056
F219: 46722 | G219: 359.16849
